Workbook

Sheet Sheet3
P3: total debt | Q3: 3818374
B4: Assumptions | J4: Discount Rate | P4: total equity | Q4: 223731
B5: Tax rate | C5: 0.3 | P5: Interest Exp | Q5: 2628000
B6: Long term growth rate | C6: 0.03
B7: Discount rate | C7: 0.08 | P7: cost of debt | Q7: =(Q5*(1-C5))/Q3 -> 0.48177575
B8: Share price | C8: 3 | Q8: =(Q5*(1-C5))/Q4 -> 8.2223742
B9: Shares outstanding | C9: 1000
B11: Year count | D11: 1 | E11: 2 | F11: 3 | G11: 4 | H11: 5
B12: EBIT | D12: 270 | E12: 247.5 | F12: 268 | G12: 280 | H12: 290
B13: Tax on EBIT | D13: =(D12*$C$5)*-1 -> -81 | E13: =(E12*$C$5)*-1 -> -74.25 | F13: =(F12*$C$5)*-1 -> -80.4 | G13: =(G12*$C$5)*-1 -> -84 | H13: =(H12*$C$5)*-1 -> -87
B14: + Depreciation and amortization | D14: 20 | E14: 22 | F14: 24.2 | G14: 26.6 | H14: 29.2
B15: - Capital expenditure | D15: -30 | E15: -33 | F15: -36.3 | G15: -39.9 | H15: -43.9
B16: Change in Net working capital | D16: -2.8 | E16: -4.2 | F16: -4.7 | G16: -1.9 | H16: -5
B17: Others
B18: Free cash flow | D18: =D12+D13+D14+D15-D16+D17 -> 181.8 | E18: =E12+E13+E14+E15-E16+E17 -> 166.45 | F18: =F12+F13+F14+F15-F16+F17 -> 180.2 | G18: =G12+G13+G14+G15-G16+G17 -> 184.6 | H18: =H12+H13+H14+H15-H16+H17 -> 193.3
B20: Terminal value | H20: =(H18*(1+C6))/(C7-C6) -> 3981.98
B22: Discount factor @ 15% | D22: =1/(1+$C$7)^D11 -> 0.92592593 | E22: =1/(1+$C$7)^E11 -> 0.85733882 | F22: =1/(1+$C$7)^F11 -> 0.79383224 | G22: =1/(1+$C$7)^G11 -> 0.73502985 | H22: =1/(1+$C$7)^H11 -> 0.6805832
B23: Present value of free cash flows | D23: =D18*D22 -> 168.33333 | E23: =E18*E22 -> 142.70405 | F23: =F18*F22 -> 143.04857 | G23: =G18*G22 -> 135.68651 | H23: =H18*H22 -> 131.55673
B25: Sum of present value of free cash flows | C25: =SUM(D23:H23) -> 721.32919
B26: Present value of terminal value | C26: =H20*H22 -> 2710.0687
B27: Enterprise value | C27: =C25+C26 -> 3431.3979
B29: + Cash | C29: 124.2
B30: - Debt | C30: -500
B31: Implied equity value (intrinsic value) | C31: =C29+C30+C27 -> 3055.5979
B33: Market capitalization | C33: =C8*C9 -> 3000
B34: Intrinsic value premium to market capitalization | C34: =C31-C33 -> 55.597872 | D34: =C34/C33 -> 0.018532624

Sheet Comparables 
A1: PAYPAY - COMPARABLE COMPANIES VALUATION
B3: Exchange Rates | D3: Source
B4: JPY / USD | C4: =1/159.65 -> 0.0062637018 | D4: Bloomberg
B5: KRW / USD | C5: =1/1510.85 -> 0.00066187907 | D5: Bloomberg
B7: Valuation Inputs | D7: Notes
B8: Primary multiple | C8: EV / Revenue | D8: Revenue multiple stays relatively more stable across comps
B9: Secondary multiple | C9: EV / EBITDA | D9: Captures differences in margin
B10: Illiquidity discount | C10: 0.2 | D10: Due to PayPay being private
B12: COMPARABLE COMPANIES DATA - LOCAL CURRENCY
B13: All figures in local currency (JPY billions PayPay, KRW billions for KakaoPay, USD Millions for Shift4)
B15: Company | C15: Market Cap | D15: EV | E15: Revenue (Last financial yr) | F15: Revenue Growth (%) | G15: Net Debt | H15: Net Debt/Equity (%) | I15: EBITDA | J15: Operating Margin (%) | K15: EV/EBITDA | L15: EV/Revenue | M15: Beta | N15: Source
B16: GMO Payment Gateway | C16: 634.8 | D16: 478.52 | E16: 82.49939 | F16: 0.1181 | H16: 0.5776 | I16: 34.99305 | J16: 0.3766 | K16: =D16/I16 -> 13.674715 | L16: =D16/E16 -> 5.8002853 | M16: 0.91
B17: Shift4 Payments, Inc. | C17: 3473.79 | D17: 7844.77 | E17: 4180 | F17: 0.2549 | I17: 853 | J17: 0.1007 | K17: =D17/I17 -> 9.1966823 | L17: =D17/E17 -> 1.8767392 | M17: 1.49 | N17: Factset
B18: KakaoPay Corp. | C18: 6480 | D18: 4359.34 | E18: 939.08 | F18: 0.256278 | I18: 95.79 | J18: 0.0493 | K18: =D18/I18 -> 45.509343 | L18: =D18/E18 -> 4.6421391 | M18: 1.11 | N18: Factset
B19: NHN KCP Corp. | C19: 581.96 | D19: 166.75124 | E19: 1234.88 | F19: 0.1172 | I19: 61.27 | J19: 0.0443 | K19: =D19/I19 -> 2.7215805 | L19: =D19/E19 -> 0.13503437 | M19: 0.95
B20: PayPay | E20: 299.078 | F20: 0.17464 | G20: 62.079 | H20: 0.133 | I20: 58.65 | J20: 0.1187 | N20: PayPay F-1 Form
B22: COMPARABLE COMPANIES DATA - USD
B23: All figures in USD millions
B25: Company | C25: =C15 -> Market Cap | D25: =D15 -> EV | E25: =E15 -> Revenue (Last financial yr) | F25: =F15 -> Revenue Growth (%) | G25: =G15 -> Net Debt | H25: =H15 -> Net Debt/Equity (%) | I25: =I15 -> EBITDA | J25: =J15 -> Operating Margin (%) | ... M25: =M15 -> Beta
B26: =B16 -> GMO Payment Gateway | C26: =$C$4*C16*1000 -> 3976.1979 | D26: =$C$4*D16*1000 -> 2997.3066 | E26: =$C$4*E16*1000 -> 516.75158 | F26: =F16 -> 0.1181 | G26: =G16*$C$4*1000 -> 0 | H26: =H16 -> 0.5776 | I26: =I16*$C$4*1000 -> 219.18603 | J26: =J16 -> 0.3766 | K26: =K16 -> 13.674715 | L26: =L16 -> 5.8002853 | M26: =M16 -> 0.91
B27: =B17 -> Shift4 Payments, Inc. | C27: =C17 -> 3473.79 | D27: =D17 -> 7844.77 | E27: =E17 -> 4180 | F27: =F17 -> 0.2549 | G27: =G17 -> 0 | H27: =H17 -> 0 | I27: =I17 -> 853 | ... M27: =M17 -> 1.49
B28: =B18 -> KakaoPay Corp. | C28: =C18*$C$5*1000 -> 4288.9764 | D28: =D18*$C$5*1000 -> 2885.3559 | E28: =E18*$C$5*1000 -> 621.5574 | F28: =F18 -> 0.256278 | G28: =G18*$C$5*1000 -> 0 | H28: =H18 -> 0 | I28: =I18*$C$5*1000 -> 63.401397 | J28: =J18 -> 0.0493 | K28: =K18 -> 45.509343 | L28: =L18 -> 4.6421391 | M28: =M18 -> 1.11
B29: =B19 -> NHN KCP Corp. | C29: =C19*$C$5*1000 -> 385.18715 | D29: =D19*$C$5*1000 -> 110.36916 | E29: =E19*$C$5*1000 -> 817.34123 | F29: =F19 -> 0.1172 | G29: =G19*$C$5*1000 -> 0 | H29: =H19 -> 0 | I29: =I19*$C$5*1000 -> 40.553331 | J29: =J19 -> 0.0443 | K29: =K19 -> 2.7215805 | L29: =L19 -> 0.13503437 | M29: =M19 -> 0.95
B30: =B20 -> PayPay | E30: =E20*$C$4*1000 -> 1873.3354 | F30: =F20 -> 0.17464 | G30: =G20*C4*1000 -> 388.84435 | I30: =I20*$C$4*1000 -> 367.36611 | J30: =J20 -> 0.1187
B32: PAYPAY FINANCIALS
B33: All figures in USD millions
B34: Item | C34: Value | D34: Notes
B35: Revenue | C35: =E30 -> 1873.3354
B36: EBITDA (adjusted) | C36: =I30 -> 367.36611
B37: Net Debt | C37: =G30 -> 388.84435 | D37: Borrowings (as at Dec 2025) - Cash
B39: FINAL COMPARABLES VALUATION
B40: All figures in USD millions
B41: Item | C41: Min | D41: Max | E41: Average | F41: Notes
B42: Implied EV | C42: =MIN(L27:L28)*C35 -> 3515.7621 | D42: =MAX(L27:L28)*C35 -> 8696.2836 | E42: =AVERAGE(L27:L28)*C35 -> 6106.0229 | F42: EV/Rev * PayPay Revenue
B43: Equity Value (pre-money) | C43: =C42-$C$37 -> 3126.9177 | D43: =D42-$C$37 -> 8307.4393 | E43: =E42-$C$37 -> 5717.1785 | F43: Implied EV - Net Debt
B44: Discounted Value | C44: =(1-$C$10)*C43 -> 2501.5342 | D44: =(1-$C$10)*D43 -> 6645.9514 | E44: =(1-$C$10)*E43 -> 4573.7428 | F44: Applying illiquidity discount

Sheet DCF Valuation
A1: PAYPAY - DCF VALUATION
B3: Market Assumptions (2025) | D3: Notes | F3: Source
B4: Digital Payment Market Size | C4: 270 | D4: USD Billions (Japanese market) | F4: Mordor Intelligence 2026
B5: Market CAGR | C5: 0.314
B6: Mobile Wallet Market Segment | C6: 0.4783 | D6: Out of digital payments market
B7: PayPay's segment share | C7: 0.64 | D7: In mobile wallet segment | F7: PayPay F-1 Form
B8: PayPay's market share | C8: =C7*C6 -> 0.306112 | D8: PayPay segment share*mobile wallet market segment
B9: PayPay expected segment share by 2031 | C9: 0.7 | D9: In mobile wallet segment (2031)
B10: PayPay's market share (2031) | C10: =C9*C6 -> 0.33481 | D10: PayPay expected segment share*mobile wallet segment
B11: Market Share CAGR | C11: =(C10/C8)^(1/6)-1 -> 0.01504745 | D11: (exp.market share/current market share)^(1/6)-1
B14: Valuation Inputs (2025) | D14: Notes | G14: Source
B15: GMV (JPY) | C15: 15390 | D15: Gross Merchandise Value | G15: PayPay F-1 Form
B16: GMV (USD) | C16: =C15*'Comparables '!C4 -> 96.398371 | D16: GMV (JPY)*(JPY/USD) rate
B17: Pretax Margin | C17: ='Comparables '!J20 -> 0.1187 | D17: Operating margins
B18: Margin CAGR | C18: =(C31/C17)^(1/6)-1 -> 0.080322771 | D18: (Expected margin (peer benchmark) / Current margin)^(1/6)-1
B19: Revenue | C19: =C16*E25 -> 1.5520138 | D19: USD Billions | G19: PayPay F-1 Form
B20: Book Debt | C20: 399578 | D20: JPY Millions
B21: Book Equity | C21: 223731 | D21: JPY Millions
B22: Tax Rate | C22: 0.3 | D22: Assumption
B24: PayPay Take Rates | C24: 2023 | D24: 2024 | E24: 2025 | F24: Average
B25: Take Rate | C25: 0.0163 | D25: 0.017 | E25: 0.0161 | F25: =AVERAGE(C25:E25) -> 0.016466667
B28: PEER BENCHMARKS
B30: PayPal
B31: Pretax Margin | C31: 0.1887
B32: Sales-to-capital ratio | C32: 2.5
B34: Company | C34: Debt | D34: Equity | E34: D/E | F34: Beta (Levered) | G34: Beta (Unlevered)
B35: Shift 4 | C35: 4616 | D35: 1957 | E35: =C35/D35 -> 2.3587123 | F35: ='Comparables '!M17 -> 1.49 | G35: =F35/(1+(1-C22)*E35) -> 0.56203115
B36: Kakaopay | C36: 1261.6 | D36: 1354.3 | E36: =C36/D36 -> 0.93155135 | F36: ='Comparables '!M18 -> 1.11 | G36: =F36/(1+(1-C22)*E36) -> 0.67187788
B38: Input | C38: Value | D38: Source
B39: Average beta (unlevered) | C39: =AVERAGE(G35:G36) -> 0.61695451
B40: Average beta (levered) | C40: =C39*(1+(1-C22)*(C20/C21)) -> 1.3882603
B41: Risk free rate | C41: 0.016 | D41: Market Risk Premia 2026
B42: Market Risk Premium | C42: 0.053
B43: Discount Rate | C43: =C41+C40*C42 -> 0.089577796
B45: DISCOUNTED CASHFLOW (DCF) VALUATION
C48: 2026 | D48: 2027 | E48: 2028 | F48: 2029 | G48: 2030 | H48: 2031
B49: Total Market | C49: =C4*(1+$C$5)^1 -> 354.78 | D49: =C49*(1+$C$5)^1 -> 466.18092 | E49: =D49*(1+$C$5)^1 -> 612.56173 | F49: =E49*(1+$C$5)^1 -> 804.90611 | G49: =F49*(1+$C$5)^1 -> 1057.6466 | H49: =G49*(1+$C$5)^1 -> 1389.7477
B50: Market Share | C50: =C8*(1+$C$11)^1 -> 0.3107182 | D50: =C50*(1+$C$11)^1 -> 0.31539372 | E50: =D50*(1+$C$11)^1 -> 0.32013959 | F50: =E50*(1+$C$11)^1 -> 0.32495688 | G50: =F50*(1+$C$11)^1 -> 0.32984665 | H50: =G50*(1+$C$11)^1 -> 0.33481
B51: GMV | C51: =C50*C49 -> 110.2366 | D51: =D50*D49 -> 147.03054 | E51: =E50*E49 -> 196.10526 | F51: =F50*F49 -> 261.55978 | G51: =G50*G49 -> 348.8612 | H51: =H50*H49 -> 465.30142
B52: Take Rate | C52: =$F$25 -> 0.016466667 | D52: =$F$25 -> 0.016466667 | E52: =$F$25 -> 0.016466667 | F52: =$F$25 -> 0.016466667 | G52: =$F$25 -> 0.016466667 | H52: =$F$25 -> 0.016466667
...

Sheet Sheet2
B1: Discount cash flow
B3: Assumptions
B4: Tax Rate | C4: 0.25
B5: Discount Rate | C5: 0.1
B6: Perpetural Growth Rate | C6: 0.03
B7: EV/EBITDA Mulltiple | C7: 33.8x
B8: Transaction Date | C8: 44196
B9: Fiscal Year End | C9: 44377
B10: Current Price | C10: 25
B11: Shares Outstanding | C11: 20000
B12: Debt | C12: 30000
B13: Cash | C13: 200000
B14: Capex | C14: 15000
B16: Discount cash flow | C16: Entry | D16: 2021 | E16: 2022 | F16: 2023 | G16: 2024 | H16: 2025 | I16: 2026 | J16: Exit | M16: Terminal Value
B17: Date | C17: =C8 -> 44196 | D17: =C9 -> 44377 | E17: 44742 | F17: 45107 | G17: 45473 | H17: 45838 | I17: 46203 | J17: 46203 | M17: Perpetual Growth | N17: =(I25*(1+C6))/(C5-C6) -> -220714.29
B18: Time Period | D18: 0 | E18: =D18+1 -> 1 | F18: =E18+1 -> 2 | G18: =F18+1 -> 3 | H18: =G18+1 -> 4 | I18: =H18+1 -> 5 | M18: EV/EBITDA | N18: =C7*(I20+I22) -> #VALUE!
B19: Year Fraction | D19: =YEARFRAC(C17,D17) -> 0.5 | E19: =YEARFRAC(D17,E17) -> 1 | F19: =YEARFRAC(E17,F17) -> 1 | G19: =YEARFRAC(F17,G17) -> 1 | H19: =YEARFRAC(G17,H17) -> 1 | I19: =YEARFRAC(H17,I17) -> 1 | M19: Average | N19: =AVERAGE(N17:N18) -> #VALUE!
B20: EBIT
B21: (Cash and Taxes) | D21: =D20*$C$4 -> 0 | E21: =E20*$C$4 -> 0 | F21: =F20*$C$4 -> 0 | G21: =G20*$C$4 -> 0 | H21: =H20*$C$4 -> 0 | I21: =I20*$C$4 -> 0
B22: D&A
B23: (Capex) | D23: =$C$14 -> 15000 | E23: =$C$14 -> 15000 | F23: =$C$14 -> 15000 | G23: =$C$14 -> 15000 | H23: =$C$14 -> 15000 | I23: =$C$14 -> 15000
B24: (Change in NWC)
B25: Unlevered FCF | D25: =D20-D21+D22-D23-D24 -> -15000 | E25: =E20-E21+E22-E23-E24 -> -15000 | F25: =F20-F21+F22-F23-F24 -> -15000 | G25: =G20-G21+G22-G23-G24 -> -15000 | H25: =H20-H21+H22-H23-H24 -> -15000 | I25: =I20-I21+I22-I23-I24 -> -15000
B26: Entry/Exit | C26: =F36 -> 330000
B27: Transaction CF | D27: =(D26+D25)*D19 -> -7500 | E27: =(E26+E25)*E19 -> -15000 | F27: =(F26+F25)*F19 -> -15000 | G27: =(G26+G25)*G19 -> -15000 | H27: =(H26+H25)*H19 -> -15000 | I27: =(I26+I25)*I19 -> -15000
B28: Transaction CF | C28: =C26+C25 -> 330000 | D28: =(D26+D25)*D19 -> -7500 | E28: =(E26+E25)*E19 -> -15000 | F28: =(F26+F25)*F19 -> -15000 | G28: =(G26+G25)*G19 -> -15000 | H28: =(H26+H25)*H19 -> -15000 | I28: =(I26+I25)*I19 -> -15000
B32: Intrinsic Value | E32: Market Value | J32: Rate Of Return
B33: Enterprise Value | C33: =NPV(C5,D25:I25,C17:I17) -> 58345.272 | E33: Market Cap | F33: =C10*C11 -> 500000 | J33: Target Price Upside | L33: =C38/F38-1 -> -0.54330946
B34: Cash | C34: =C13 -> 200000 | E34: Debt | F34: =C12 -> 30000 | J34: Internal Rate of Return (IRR) | L34: 0.25
B35: (Debt) | C35: =C12 -> 30000 | E35: (Cash) | F35: =C13 -> 200000
B36: Equity Value | C36: =C33+C34-C35 -> 228345.27 | E36: Enterprise Value | F36: =F33+F34-F35 -> 330000 | J36: Market Value vs Intrinsic Value
J37: Market Value | L37: =F38 -> 25
B38: Equity Value/Share | C38: =C36/C11 -> 11.417264 | E38: Equity Value/Share | F38: 25 | J38: Upside | L38: =C38 -> 11.417264
J39: Intrinsic Value | L39: =L37+L38 -> 36.417264

Sheet First Chicago
A1: PAYPAY - FIRST CHICAGO METHOD VALUATION
B2: Failure Case - Assume PayPay holds only 30% of the market segment by 2031
B3: PayPay's market segment (2031) | C3: 0.3 | D3: (of Mobile Wallet segment)
B4: PayPay's market share (2031) | C4: =C3*'DCF Valuation'!C6 -> 0.14349 | D4: PayPay segment * Mobile wallet share
B5: Market Share CAGR | C5: =(C4/'DCF Valuation'!C8)^(1/6)-1 -> -0.11863281 | D5: (exp.market share/current market share)^(1/6)-1
B6: Netstars Co Peer Benchmark
B7: Pre-tax margin | C7: 0.084
B8: Margin CAGR | C8: =(C7/'DCF Valuation'!C17)^(1/6)-1 -> -0.056001231 | D8: (Failure margin / Current margin)^(1/6)-1
B9: Sales-to-capital ratio | C9: 0.73
C11: 2026 | D11: 2027 | E11: 2028 | F11: 2029 | G11: 2030 | H11: 2031
B12: Total Market | C12: {='DCF Valuation'!C49:H49} -> 354.78 | D12: 466.18092 | E12: 612.56173 | F12: 804.90611 | G12: 1057.6466 | H12: 1389.7477
B13: Market Share | C13: ='DCF Valuation'!C8*(1+$C$5)^1 -> 0.26979707 | D13: =C13*(1+$C$5)^1 -> 0.23779029 | E13: =D13*(1+$C$5)^1 -> 0.20958056 | F13: =E13*(1+$C$5)^1 -> 0.18471743 | G13: =F13*(1+$C$5)^1 -> 0.16280388 | H13: =G13*(1+$C$5)^1 -> 0.14349
B14: GMV | C14: =C13*C12 -> 95.718606 | D14: =D13*D12 -> 110.8533 | E14: =E13*E12 -> 128.38103 | F14: =F13*F12 -> 148.68019 | G14: =G13*G12 -> 172.18898 | H14: =H13*H12 -> 199.41489
B15: Take Rate | C15: 0.012 | D15: 0.012 | E15: 0.012 | F15: 0.012 | G15: 0.012 | H15: 0.012
B16: Revenue | C16: =C14*C15 -> 1.1486233 | D16: =D14*D15 -> 1.3302395 | E16: =E14*E15 -> 1.5405724 | F16: =F14*F15 -> 1.7841623 | G16: =G14*G15 -> 2.0662677 | H16: =H14*H15 -> 2.3929787
B17: Pretax Margin | C17: ='DCF Valuation'!$C$17*(1+$C$8)^1 -> 0.11205265 | D17: =C17*(1+$C$8)^1 -> 0.10577757 | E17: =D17*(1+$C$8)^1 -> 0.099853893 | F17: =E17*(1+$C$8)^1 -> 0.094261952 | G17: =F17*(1+$C$8)^1 -> 0.088983167 | H17: =G17*(1+$C$8)^1 -> 0.084
B18: EBIT | C18: =C16*C17 -> 0.12870629 | D18: =D16*D17 -> 0.1407095 | E18: =E16*E17 -> 0.15383215 | F18: =F16*F17 -> 0.16817862 | G18: =G16*G17 -> 0.18386305 | H18: =H16*H17 -> 0.20101021
B20: Taxes | C20: ='DCF Valuation'!$C$22*C18 -> 0.038611886 | D20: ='DCF Valuation'!$C$22*D18 -> 0.042212851 | E20: ='DCF Valuation'!$C$22*E18 -> 0.046149644 | F20: ='DCF Valuation'!$C$22*F18 -> 0.050453585 | G20: ='DCF Valuation'!$C$22*G18 -> 0.055158914 | H20: ='DCF Valuation'!$C$22*H18 -> 0.060303064
B21: EBIAT | C21: =C18-C20 -> 0.0900944 | D21: =D18-D20 -> 0.098496652 | E21: =E18-E20 -> 0.1076825 | F21: =F18-F20 -> 0.11772503 | G21: =G18-G20 -> 0.12870413 | H21: =H18-H20 -> 0.14070715
B23: Changes in revenue | C23: =C16-'DCF Valuation'!C19 -> -0.40339051 | D23: =D16-C16 -> 0.18161628 | E23: =E16-D16 -> 0.21033281 | F23: =F16-E16 -> 0.24358989 | G23: =G16-F16 -> 0.28210547 | H23: =H16-G16 -> 0.326711
B24: Sales/Capital | C24: =$C$9 -> 0.73 | D24: =$C$9 -> 0.73 | E24: =$C$9 -> 0.73 | F24: =$C$9 -> 0.73 | G24: =$C$9 -> 0.73 | H24: =$C$9 -> 0.73
B25: Reinvestment | C25: =C23/C24 -> -0.55258974 | D25: =D23/D24 -> 0.24878942 | E25: =E23/E24 -> 0.28812713 | F25: =F23/F24 -> 0.33368479 | G25: =G23/G24 -> 0.38644585 | H25: =H23/H24 -> 0.44754931
J26: Terminal Value
B27: FCFF | C27: =C21-C25 -> 0.64268414 | D27: =D21-D25 -> -0.15029277 | E27: =E21-E25 -> -0.18044463 | F27: =F21-F25 -> -0.21595975 | G27: =G21-G25 -> -0.25774172 | H27: =H21-H25 -> -0.30684217 | J27: r | K27: ='DCF Valuation'!C43 -> 0.089577796 | L27: From DCF
B28: DF @ 8.96% | C28: =(1+'DCF Valuation'!$C$43)^1 -> 1.0895778 | D28: =(1+'DCF Valuation'!$C$43)^2 -> 1.1871798 | E28: =(1+'DCF Valuation'!$C$43)^3 -> 1.2935247 | F28: =(1+'DCF Valuation'!$C$43)^4 -> 1.4093958 | G28: =(1+'DCF Valuation'!$C$43)^5 -> 1.5356464 | H28: =(1+'DCF Valuation'!$C$43)^6 -> 1.6732062 | J28: g | K28: 0.02 | L28: Assuming 2% terminal growth
B29: PV(FCFF) | C29: =C27/C28 -> 0.58984695 | D29: =D27/D28 -> -0.12659647 | E29: =E27/E28 -> -0.1394984 | F29: =F27/F28 -> -0.1532286 | G29: =G27/G28 -> -0.16783924 | H29: =H27/H28 -> -0.18338574 | J29: TV | K29: =(H27*(1+K28))/(K27-K28) -> -4.4982599 | L29: FCFF*(1+g)/(r-g)
B30: Total PV | H30: =SUM(C29:H29) -> -0.18070151 | J30: PV(TV) | K30: =K29/((1+K27)^6) -> -2.6884074 | L30: TV/(1+r)^6
B32: Success Case - PayPay reaches PayPal's Market Share by 2031
B33: Market Assumptions (2026)
B34: Global Digital Payment Market Size | C34: 26890 | D34: USD billions
B35: Market CAGR | C35: 0.0763 | D35: Global Digital Payments Market
B36: Global Mobile Payment Market Size | C36: 18950 | D36: Segment of Digital Payments
B37: PayPal Mobile Payments | C37: 1793.98 | D37: PayPal Mobile Payments Revenue
B38: Mobile Payment Market Segment | C38: =C36/C34 -> 0.70472295 | D38: Mobile Payment / Digital Payments
B39: PayPal's segment share | C39: =C37/C36 -> 0.094669129 | D39: PayPal Mobile Payments / Global Mobile Payments
B40: PayPal's market share | C40: =C39*C38 -> 0.066715508 | D40: of Global Digital Payments Market
B41: PayPay's segment share | C41: ='DCF Valuation'!C16/C36 -> 0.0050869853 | D41: of Global Mobile Payments Segment
B42: PayPay's market share | C42: =C41*C38 -> 0.0035849153 | D42: of Global Digital Payments Market
B44: Assume PayPay reach the same amount of global market share as PayPal by 2031
B45: PayPay's market share (2031) | C45: =C40 -> 0.066715508 | D45: PayPal's current market share
...

Sheet VC Method
A1: PAYPAY - VC METHOD VALUATION
B3: Assume PayPay is going to exit after 6 years (in 2031)
B4: Revenue | C4: ='Comparables '!E30/1000 -> 1.8733354 | D4: USD Billions
B5: Growth Rate | C5: 0.31 | D5: Assumed using market CAGR
B6: Revenue (2031) | C6: =C4*(1+C5)^6 -> 9.4676745 | D6: Revenue*(1+g)^6
B7: Target IRR | C7: 0.25 | D7: IPO-ready stage
B9: All figures in USD Billions
B10: Comparable firm | C10: EV / Revenue | D10: Exit EV | E10: Exit Equity Value | F10: PV (Equity Value) | G10: Equity Value (after discount)
B11: Shift4 Payments | C11: ='Comparables '!L27 -> 1.8767392 | D11: =C6*C11 -> 17.768356 | E11: =D11-('Comparables '!C37/1000) -> 17.379512 | F11: =E11/(1+C7)^6 -> 4.5559348 | G11: =F11*(1-'Comparables '!$C$10) -> 3.6447478
B12: Kakaopay | C12: ='Comparables '!L28 -> 4.6421391 | D12: =C6*C12 -> 43.950262 | E12: =D12-('Comparables '!C38/1000) -> 43.950262 | F12: =E12/(1+C7)^6 -> 11.521298 | G12: =F12*(1-'Comparables '!$C$10) -> 9.217038

Sheet Final Valuation
A1: FINAL VALUATION - TRIANGULATION
B2: Valuation Method | C2: Minimum | D2: Difference | E2: Maximum | F2: Expected
B3: EV / Revenue | C3: ='Comparables '!C44/1000 -> 2.5015342 | D3: =E3-C3 -> 4.1444172 | E3: ='Comparables '!D44/1000 -> 6.6459514 | F3: =AVERAGE(C3,E3) -> 4.5737428
B4: VC | C4: ='VC Method'!G11 -> 3.6447478 | D4: =E4-C4 -> 5.5722902 | E4: ='VC Method'!G12 -> 9.217038 | F4: =AVERAGE(C4,E4) -> 6.4308929
B5: DCF | C5: ='DCF Valuation'!E90*(1-'Comparables '!C10) -> 1.1175456 | D5: =E5-C5 -> 3.3864406 | E5: ='DCF Valuation'!C92*(1-'Comparables '!C10) -> 4.5039862 | F5: ='DCF Valuation'!C77 -> 1.9771127
B6: First Chicago | C6: ='DCF Valuation'!C77 -> 1.9771127 | D6: =E6-C6 -> 4.5216035 | E6: ='First Chicago'!C82 -> 6.4987162 | F6: ='First Chicago'!C82 -> 6.4987162
B8: Valuation Method | C8: Weight
B9: EV / Revenue | C9: 0.3
B10: VC | C10: 0.1
B11: DCF | C11: 0.4
B12: First Chicago | C12: 0.2
B14: Equity Value (discounted - $b) | C14: =SUMPRODUCT(C9:C12,F3:F6) -> 4.1058005
B15: Number of Existing Shares | C15: ='Cap Table'!F4+'Cap Table'!F5 -> 626074840
B16: Share Price | C16: =C14/C15*1000000000 -> 6.5580026

Sheet Cap Table
A1: CAP TABLE
B3: Individual or Entity | C3: OPP | D3: Amount invested ($m) | E3: Conversion Price | F3: Common Shares Equivalent | G3: % Own (fully diluted) | H3: Notes
B4: Existing shareholders - Common Shares | C4: 5.11 | D4: =C4*F4/1000000 -> 3135.6914 | E4: - | F4: 613638240 | G4: =F4/F7 -> 0.82030267
B5: Stock Options | C5: - | D5: - | E5: - | F5: 12436600 | G5: =F5/F7 -> 0.016625066
B6: New investor - Convertible Preferred Shares | C6: ='Final Valuation'!C16 -> 6.5580026 | D6: 800 | E6: =C6 -> 6.5580026 | F6: =D6*1000000/C6 -> 1.2198836e+08 | G6: =F6/F7 -> 0.16307227 | H6: Conversion Price is subjected to the anti-dilution term.
B7: Total | D7: =SUM(D4:D6) -> 3935.6914 | E7: - | F7: =SUM(F4:F6) -> 7.480632e+08 | G7: =SUM(G4:G6) -> 1
